Traceback (most recent call last):
  File "E:\DataAnalysis\python_project\project\auto_reply_robot\utility\sql_helper.py", line 148, in fetch_one
    cursor.execute(sql, *params)
  File "E:\DataAnalysis\Anaconda3\lib\site-packages\pymysql\cursors.py", line 170, in execute
    result = self._query(query)
  File "E:\DataAnalysis\Anaconda3\lib\site-packages\pymysql\cursors.py", line 328, in _query
    conn.query(q)
  File "E:\DataAnalysis\Anaconda3\lib\site-packages\pymysql\connections.py", line 517, in query
    self._affected_rows = self._read_query_result(unbuffered=unbuffered)
  File "E:\DataAnalysis\Anaconda3\lib\site-packages\pymysql\connections.py", line 732, in _read_query_result
    result.read()
  File "E:\DataAnalysis\Anaconda3\lib\site-packages\pymysql\connections.py", line 1075, in read
    first_packet = self.connection._read_packet()
  File "E:\DataAnalysis\Anaconda3\lib\site-packages\pymysql\connections.py", line 684, in _read_packet
    packet.check_error()
  File "E:\DataAnalysis\Anaconda3\lib\site-packages\pymysql\protocol.py", line 220, in check_error
    err.raise_mysql_exception(self._data)
  File "E:\DataAnalysis\Anaconda3\lib\site-packages\pymysql\err.py", line 109, in raise_mysql_exception
    raise errorclass(errno, errval)
pymysql.err.ProgrammingError: (1146, "Table 'pymysql.admin' doesn't exist")
Traceback (most recent call last):
  File "E:\DataAnalysis\python_project\project\auto_reply_robot\utility\sql_helper.py", line 152, in fetch_one
    cursor.execute(sql, *params)
  File "E:\DataAnalysis\Anaconda3\lib\site-packages\pymysql\cursors.py", line 170, in execute
    result = self._query(query)
  File "E:\DataAnalysis\Anaconda3\lib\site-packages\pymysql\cursors.py", line 328, in _query
    conn.query(q)
  File "E:\DataAnalysis\Anaconda3\lib\site-packages\pymysql\connections.py", line 517, in query
    self._affected_rows = self._read_query_result(unbuffered=unbuffered)
  File "E:\DataAnalysis\Anaconda3\lib\site-packages\pymysql\connections.py", line 732, in _read_query_result
    result.read()
  File "E:\DataAnalysis\Anaconda3\lib\site-packages\pymysql\connections.py", line 1075, in read
    first_packet = self.connection._read_packet()
  File "E:\DataAnalysis\Anaconda3\lib\site-packages\pymysql\connections.py", line 684, in _read_packet
    packet.check_error()
  File "E:\DataAnalysis\Anaconda3\lib\site-packages\pymysql\protocol.py", line 220, in check_error
    err.raise_mysql_exception(self._data)
  File "E:\DataAnalysis\Anaconda3\lib\site-packages\pymysql\err.py", line 109, in raise_mysql_exception
    raise errorclass(errno, errval)
pymysql.err.ProgrammingError: (1146, "Table 'pymysql.users_log_table' doesn't exist")
Traceback (most recent call last):
  File "E:\DataAnalysis\python_project\project\auto_reply_robot\utility\sql_helper.py", line 93, in insert
    count = cursor.executemany(sql, params)
  File "E:\DataAnalysis\Anaconda3\lib\site-packages\pymysql\cursors.py", line 197, in executemany
    self._get_db().encoding)
  File "E:\DataAnalysis\Anaconda3\lib\site-packages\pymysql\cursors.py", line 234, in _do_execute_many
    rows += self.execute(sql + postfix)
  File "E:\DataAnalysis\Anaconda3\lib\site-packages\pymysql\cursors.py", line 170, in execute
    result = self._query(query)
  File "E:\DataAnalysis\Anaconda3\lib\site-packages\pymysql\cursors.py", line 328, in _query
    conn.query(q)
  File "E:\DataAnalysis\Anaconda3\lib\site-packages\pymysql\connections.py", line 517, in query
    self._affected_rows = self._read_query_result(unbuffered=unbuffered)
  File "E:\DataAnalysis\Anaconda3\lib\site-packages\pymysql\connections.py", line 732, in _read_query_result
    result.read()
  File "E:\DataAnalysis\Anaconda3\lib\site-packages\pymysql\connections.py", line 1075, in read
    first_packet = self.connection._read_packet()
  File "E:\DataAnalysis\Anaconda3\lib\site-packages\pymysql\connections.py", line 684, in _read_packet
    packet.check_error()
  File "E:\DataAnalysis\Anaconda3\lib\site-packages\pymysql\protocol.py", line 220, in check_error
    err.raise_mysql_exception(self._data)
  File "E:\DataAnalysis\Anaconda3\lib\site-packages\pymysql\err.py", line 109, in raise_mysql_exception
    raise errorclass(errno, errval)
pymysql.err.ProgrammingError: (1146, "Table 'pymysql.users_log_table' doesn't exist")
Traceback (most recent call last):
  File "E:\DataAnalysis\python_project\project\auto_reply_robot\utility\sql_helper.py", line 93, in insert
    count = cursor.executemany(sql, params)
  File "E:\DataAnalysis\Anaconda3\lib\site-packages\pymysql\cursors.py", line 197, in executemany
    self._get_db().encoding)
  File "E:\DataAnalysis\Anaconda3\lib\site-packages\pymysql\cursors.py", line 234, in _do_execute_many
    rows += self.execute(sql + postfix)
  File "E:\DataAnalysis\Anaconda3\lib\site-packages\pymysql\cursors.py", line 170, in execute
    result = self._query(query)
  File "E:\DataAnalysis\Anaconda3\lib\site-packages\pymysql\cursors.py", line 328, in _query
    conn.query(q)
  File "E:\DataAnalysis\Anaconda3\lib\site-packages\pymysql\connections.py", line 517, in query
    self._affected_rows = self._read_query_result(unbuffered=unbuffered)
  File "E:\DataAnalysis\Anaconda3\lib\site-packages\pymysql\connections.py", line 732, in _read_query_result
    result.read()
  File "E:\DataAnalysis\Anaconda3\lib\site-packages\pymysql\connections.py", line 1075, in read
    first_packet = self.connection._read_packet()
  File "E:\DataAnalysis\Anaconda3\lib\site-packages\pymysql\connections.py", line 684, in _read_packet
    packet.check_error()
  File "E:\DataAnalysis\Anaconda3\lib\site-packages\pymysql\protocol.py", line 220, in check_error
    err.raise_mysql_exception(self._data)
  File "E:\DataAnalysis\Anaconda3\lib\site-packages\pymysql\err.py", line 109, in raise_mysql_exception
    raise errorclass(errno, errval)
pymysql.err.InternalError: (1136, "Column count doesn't match value count at row 1")
Traceback (most recent call last):
  File "E:\DataAnalysis\python_project\project\auto_reply_robot\utility\sql_helper.py", line 151, in fetch_one
    cursor.execute(sql, *params)
  File "E:\DataAnalysis\Anaconda3\lib\site-packages\pymysql\cursors.py", line 170, in execute
    result = self._query(query)
  File "E:\DataAnalysis\Anaconda3\lib\site-packages\pymysql\cursors.py", line 328, in _query
    conn.query(q)
  File "E:\DataAnalysis\Anaconda3\lib\site-packages\pymysql\connections.py", line 517, in query
    self._affected_rows = self._read_query_result(unbuffered=unbuffered)
  File "E:\DataAnalysis\Anaconda3\lib\site-packages\pymysql\connections.py", line 732, in _read_query_result
    result.read()
  File "E:\DataAnalysis\Anaconda3\lib\site-packages\pymysql\connections.py", line 1075, in read
    first_packet = self.connection._read_packet()
  File "E:\DataAnalysis\Anaconda3\lib\site-packages\pymysql\connections.py", line 684, in _read_packet
    packet.check_error()
  File "E:\DataAnalysis\Anaconda3\lib\site-packages\pymysql\protocol.py", line 220, in check_error
    err.raise_mysql_exception(self._data)
  File "E:\DataAnalysis\Anaconda3\lib\site-packages\pymysql\err.py", line 109, in raise_mysql_exception
    raise errorclass(errno, errval)
pymysql.err.InternalError: (1054, "Unknown column '李斯' in 'where clause'")
Traceback (most recent call last):
  File "E:\DataAnalysis\python_project\project\auto_reply_robot\utility\sql_helper.py", line 151, in fetch_one
    cursor.execute(sql, *params)
  File "E:\DataAnalysis\Anaconda3\lib\site-packages\pymysql\cursors.py", line 170, in execute
    result = self._query(query)
  File "E:\DataAnalysis\Anaconda3\lib\site-packages\pymysql\cursors.py", line 328, in _query
    conn.query(q)
  File "E:\DataAnalysis\Anaconda3\lib\site-packages\pymysql\connections.py", line 517, in query
    self._affected_rows = self._read_query_result(unbuffered=unbuffered)
  File "E:\DataAnalysis\Anaconda3\lib\site-packages\pymysql\connections.py", line 732, in _read_query_result
    result.read()
  File "E:\DataAnalysis\Anaconda3\lib\site-packages\pymysql\connections.py", line 1075, in read
    first_packet = self.connection._read_packet()
  File "E:\DataAnalysis\Anaconda3\lib\site-packages\pymysql\connections.py", line 684, in _read_packet
    packet.check_error()
  File "E:\DataAnalysis\Anaconda3\lib\site-packages\pymysql\protocol.py", line 220, in check_error
    err.raise_mysql_exception(self._data)
  File "E:\DataAnalysis\Anaconda3\lib\site-packages\pymysql\err.py", line 109, in raise_mysql_exception
    raise errorclass(errno, errval)
pymysql.err.InternalError: (1054, "Unknown column '李斯' in 'where clause'")
Traceback (most recent call last):
  File "E:\DataAnalysis\python_project\project\auto_reply_robot\utility\sql_helper.py", line 151, in fetch_one
    cursor.execute(sql, *params)
  File "E:\DataAnalysis\Anaconda3\lib\site-packages\pymysql\cursors.py", line 170, in execute
    result = self._query(query)
  File "E:\DataAnalysis\Anaconda3\lib\site-packages\pymysql\cursors.py", line 328, in _query
    conn.query(q)
  File "E:\DataAnalysis\Anaconda3\lib\site-packages\pymysql\connections.py", line 517, in query
    self._affected_rows = self._read_query_result(unbuffered=unbuffered)
  File "E:\DataAnalysis\Anaconda3\lib\site-packages\pymysql\connections.py", line 732, in _read_query_result
    result.read()
  File "E:\DataAnalysis\Anaconda3\lib\site-packages\pymysql\connections.py", line 1075, in read
    first_packet = self.connection._read_packet()
  File "E:\DataAnalysis\Anaconda3\lib\site-packages\pymysql\connections.py", line 684, in _read_packet
    packet.check_error()
  File "E:\DataAnalysis\Anaconda3\lib\site-packages\pymysql\protocol.py", line 220, in check_error
    err.raise_mysql_exception(self._data)
  File "E:\DataAnalysis\Anaconda3\lib\site-packages\pymysql\err.py", line 109, in raise_mysql_exception
    raise errorclass(errno, errval)
pymysql.err.InternalError: (1054, "Unknown column '李斯' in 'where clause'")
